package com.darkteam.thedarkera.generation;

import java.util.Random;

import com.darkteam.thedarkera.blocks.ModBlocks;

import net.minecraft.init.Blocks;
import net.minecraft.world.World;
import net.minecraft.world.gen.feature.WorldGenerator;


public class WorldGenSamDungeon extends WorldGenerator
{
	public boolean generate(World world, Random rand, int x, int y, int z) 
	{
		world.setBlock(x + 0, y + 0, z + 0, ModBlocks.samStone, 1, 2);
		world.setBlock(x + 0, y + 0, z + 1, ModBlocks.samStone, 1, 2);
		world.setBlock(x + 0, y + 0, z + 2, ModBlocks.samStone, 1, 2);
		world.setBlock(x + 0, y + 0, z + 3, ModBlocks.samStone, 1, 2);
		world.setBlock(x + 0, y + 0, z + 4, ModBlocks.samStone, 1, 2);
		world.setBlock(x + 0, y + 0, z + 5, ModBlocks.samStone, 1, 2);
		world.setBlock(x + 0, y + 0, z + 6, ModBlocks.samStone, 1, 2);
		world.setBlock(x + 0, y + 0, z + 7, ModBlocks.samStone, 1, 2);
		world.setBlock(x + 0, y + 0, z + 8, ModBlocks.samStone, 1, 2);
		world.setBlock(x + 0, y + 0, z + 9, ModBlocks.samStone, 1, 2);
		world.setBlock(x + 0, y + 0, z + 10, ModBlocks.samStone, 1, 2);
		world.setBlock(x + 0, y + 1, z + 0, ModBlocks.samStone, 1, 2);
		world.setBlock(x + 0, y + 1, z + 1, ModBlocks.samStone, 1, 2);
		world.setBlock(x + 0, y + 1, z + 2, ModBlocks.samStone, 1, 2);
		world.setBlock(x + 0, y + 1, z + 3, ModBlocks.samStone, 1, 2);
		world.setBlock(x + 0, y + 1, z + 4, ModBlocks.samStone, 1, 2);
		world.setBlock(x + 0, y + 1, z + 5, ModBlocks.samStone, 1, 2);
		world.setBlock(x + 0, y + 1, z + 6, ModBlocks.samStone, 1, 2);
		world.setBlock(x + 0, y + 1, z + 7, ModBlocks.samStone, 1, 2);
		world.setBlock(x + 0, y + 1, z + 8, ModBlocks.samStone, 1, 2);
		world.setBlock(x + 0, y + 1, z + 9, ModBlocks.samStone, 1, 2);
		world.setBlock(x + 0, y + 1, z + 10, ModBlocks.samStone, 1, 2);
		world.setBlock(x + 0, y + 2, z + 0, ModBlocks.samStone, 1, 2);
		world.setBlock(x + 0, y + 2, z + 1, ModBlocks.samStone, 1, 2);
		world.setBlock(x + 0, y + 2, z + 2, ModBlocks.samStone, 1, 2);
		world.setBlock(x + 0, y + 2, z + 3, ModBlocks.samStone, 1, 2);
		world.setBlock(x + 0, y + 2, z + 4, ModBlocks.samStone, 1, 2);
		world.setBlock(x + 0, y + 2, z + 5, ModBlocks.samStone, 1, 2);
		world.setBlock(x + 0, y + 2, z + 6, ModBlocks.samStone, 1, 2);
		world.setBlock(x + 0, y + 2, z + 7, ModBlocks.samStone, 1, 2);
		world.setBlock(x + 0, y + 2, z + 8, ModBlocks.samStone, 1, 2);
		world.setBlock(x + 0, y + 2, z + 9, ModBlocks.samStone, 1, 2);
		world.setBlock(x + 0, y + 2, z + 10, ModBlocks.samStone, 1, 2);
		world.setBlock(x + 0, y + 3, z + 0, ModBlocks.samStone, 1, 2);
		world.setBlock(x + 0, y + 3, z + 1, ModBlocks.samStone, 1, 2);
		world.setBlock(x + 0, y + 3, z + 2, ModBlocks.samStone, 1, 2);
		world.setBlock(x + 0, y + 3, z + 3, ModBlocks.samStone, 1, 2);
		world.setBlock(x + 0, y + 3, z + 4, ModBlocks.samStone, 1, 2);
		world.setBlock(x + 0, y + 3, z + 5, ModBlocks.samStone, 1, 2);
		world.setBlock(x + 0, y + 3, z + 6, ModBlocks.samStone, 1, 2);
		world.setBlock(x + 0, y + 3, z + 7, ModBlocks.samStone, 1, 2);
		world.setBlock(x + 0, y + 3, z + 8, ModBlocks.samStone, 1, 2);
		world.setBlock(x + 0, y + 3, z + 9, ModBlocks.samStone, 1, 2);
		world.setBlock(x + 0, y + 3, z + 10, ModBlocks.samStone, 1, 2);
		world.setBlock(x + 0, y + 4, z + 0, ModBlocks.samStone, 1, 2);
		world.setBlock(x + 0, y + 4, z + 1, ModBlocks.samStone, 1, 2);
		world.setBlock(x + 0, y + 4, z + 2, ModBlocks.samStone, 1, 2);
		world.setBlock(x + 0, y + 4, z + 3, ModBlocks.samStone, 1, 2);
		world.setBlock(x + 0, y + 4, z + 4, ModBlocks.samStone, 1, 2);
		world.setBlock(x + 0, y + 4, z + 5, ModBlocks.samStone, 1, 2);
		world.setBlock(x + 0, y + 4, z + 6, ModBlocks.samStone, 1, 2);
		world.setBlock(x + 0, y + 4, z + 7, ModBlocks.samStone, 1, 2);
		world.setBlock(x + 0, y + 4, z + 8, ModBlocks.samStone, 1, 2);
		world.setBlock(x + 0, y + 4, z + 9, ModBlocks.samStone, 1, 2);
		world.setBlock(x + 0, y + 4, z + 10, ModBlocks.samStone, 1, 2);
		world.setBlock(x + 0, y + 5, z + 0, ModBlocks.samStone, 1, 2);
		world.setBlock(x + 0, y + 5, z + 1, ModBlocks.samStone, 1, 2);
		world.setBlock(x + 0, y + 5, z + 2, ModBlocks.samStone, 1, 2);
		world.setBlock(x + 0, y + 5, z + 3, ModBlocks.samStone, 1, 2);
		world.setBlock(x + 0, y + 5, z + 4, ModBlocks.samStone, 1, 2);
		world.setBlock(x + 0, y + 5, z + 5, ModBlocks.samStone, 1, 2);
		world.setBlock(x + 0, y + 5, z + 6, ModBlocks.samStone, 1, 2);
		world.setBlock(x + 0, y + 5, z + 7, ModBlocks.samStone, 1, 2);
		world.setBlock(x + 0, y + 5, z + 8, ModBlocks.samStone, 1, 2);
		world.setBlock(x + 0, y + 5, z + 9, ModBlocks.samStone, 1, 2);
		world.setBlock(x + 0, y + 5, z + 10, ModBlocks.samStone, 1, 2);
		world.setBlock(x + 1, y + 0, z + 0, ModBlocks.samStone, 1, 2);
		world.setBlock(x + 1, y + 0, z + 1, ModBlocks.samStone, 1, 2);
		world.setBlock(x + 1, y + 0, z + 2, ModBlocks.samStone, 1, 2);
		world.setBlock(x + 1, y + 0, z + 3, ModBlocks.samStone, 1, 2);
		world.setBlock(x + 1, y + 0, z + 4, ModBlocks.samStone, 1, 2);
		world.setBlock(x + 1, y + 0, z + 5, ModBlocks.samStone, 1, 2);
		world.setBlock(x + 1, y + 0, z + 6, ModBlocks.samStone, 1, 2);
		world.setBlock(x + 1, y + 0, z + 7, ModBlocks.samStone, 1, 2);
		world.setBlock(x + 1, y + 0, z + 8, ModBlocks.samStone, 1, 2);
		world.setBlock(x + 1, y + 0, z + 9, ModBlocks.samStone, 1, 2);
		world.setBlock(x + 1, y + 0, z + 10, ModBlocks.samStone, 1, 2);
		world.setBlock(x + 1, y + 1, z + 0, ModBlocks.samStone, 1, 2);
		world.setBlock(x + 1, y + 1, z + 1, Blocks.air);
		world.setBlock(x + 1, y + 1, z + 2, Blocks.air);
		world.setBlock(x + 1, y + 1, z + 3, Blocks.air);
		world.setBlock(x + 1, y + 1, z + 4, Blocks.air);
		world.setBlock(x + 1, y + 1, z + 5, ModBlocks.samStone, 1, 2);
		world.setBlock(x + 1, y + 1, z + 6, Blocks.air);
		world.setBlock(x + 1, y + 1, z + 7, Blocks.air);
		world.setBlock(x + 1, y + 1, z + 8, Blocks.air);
		world.setBlock(x + 1, y + 1, z + 9, Blocks.air);
		world.setBlock(x + 1, y + 1, z + 10, ModBlocks.samStone, 1, 2);
		world.setBlock(x + 1, y + 2, z + 0, ModBlocks.samStone, 1, 2);
		world.setBlock(x + 1, y + 2, z + 1, Blocks.air);
		world.setBlock(x + 1, y + 2, z + 2, Blocks.air);
		world.setBlock(x + 1, y + 2, z + 3, Blocks.air);
		world.setBlock(x + 1, y + 2, z + 4, Blocks.air);
		world.setBlock(x + 1, y + 2, z + 5, ModBlocks.samStone, 1, 2);
		world.setBlock(x + 1, y + 2, z + 6, Blocks.air);
		world.setBlock(x + 1, y + 2, z + 7, Blocks.air);
		world.setBlock(x + 1, y + 2, z + 8, Blocks.air);
		world.setBlock(x + 1, y + 2, z + 9, Blocks.air);
		world.setBlock(x + 1, y + 2, z + 10, ModBlocks.samStone, 1, 2);
		world.setBlock(x + 1, y + 3, z + 0, ModBlocks.samStone, 1, 2);
		world.setBlock(x + 1, y + 3, z + 1, Blocks.air);
		world.setBlock(x + 1, y + 3, z + 2, Blocks.air);
		world.setBlock(x + 1, y + 3, z + 3, Blocks.air);
		world.setBlock(x + 1, y + 3, z + 4, Blocks.air);
		world.setBlock(x + 1, y + 3, z + 5, ModBlocks.samStone, 1, 2);
		world.setBlock(x + 1, y + 3, z + 6, Blocks.air);
		world.setBlock(x + 1, y + 3, z + 7, Blocks.air);
		world.setBlock(x + 1, y + 3, z + 8, Blocks.air);
		world.setBlock(x + 1, y + 3, z + 9, Blocks.air);
		world.setBlock(x + 1, y + 3, z + 10, ModBlocks.samStone, 1, 2);
		world.setBlock(x + 1, y + 4, z + 0, ModBlocks.samStone, 1, 2);
		world.setBlock(x + 1, y + 4, z + 1, Blocks.air);
		world.setBlock(x + 1, y + 4, z + 2, Blocks.air);
		world.setBlock(x + 1, y + 4, z + 3, Blocks.air);
		world.setBlock(x + 1, y + 4, z + 4, Blocks.air);
		world.setBlock(x + 1, y + 4, z + 5, Blocks.air);
		world.setBlock(x + 1, y + 4, z + 6, Blocks.air);
		world.setBlock(x + 1, y + 4, z + 7, Blocks.air);
		world.setBlock(x + 1, y + 4, z + 8, Blocks.air);
		world.setBlock(x + 1, y + 4, z + 9, Blocks.air);
		world.setBlock(x + 1, y + 4, z + 10, ModBlocks.samStone, 1, 2);
		world.setBlock(x + 1, y + 5, z + 0, ModBlocks.samStone, 1, 2);
		world.setBlock(x + 1, y + 5, z + 1, ModBlocks.samStone, 1, 2);
		world.setBlock(x + 1, y + 5, z + 2, ModBlocks.samStone, 1, 2);
		world.setBlock(x + 1, y + 5, z + 3, ModBlocks.samStone, 1, 2);
		world.setBlock(x + 1, y + 5, z + 4, ModBlocks.samStone, 1, 2);
		world.setBlock(x + 1, y + 5, z + 5, ModBlocks.samStone, 1, 2);
		world.setBlock(x + 1, y + 5, z + 6, ModBlocks.samStone, 1, 2);
		world.setBlock(x + 1, y + 5, z + 7, ModBlocks.samStone, 1, 2);
		world.setBlock(x + 1, y + 5, z + 8, ModBlocks.samStone, 1, 2);
		world.setBlock(x + 1, y + 5, z + 9, ModBlocks.samStone, 1, 2);
		world.setBlock(x + 1, y + 5, z + 10, ModBlocks.samStone, 1, 2);
		world.setBlock(x + 2, y + 0, z + 0, ModBlocks.samStone, 1, 2);
		world.setBlock(x + 2, y + 0, z + 1, ModBlocks.samStone, 1, 2);
		world.setBlock(x + 2, y + 0, z + 2, ModBlocks.samStone, 1, 2);
		world.setBlock(x + 2, y + 0, z + 3, ModBlocks.samStone, 1, 2);
		world.setBlock(x + 2, y + 0, z + 4, ModBlocks.samStone, 1, 2);
		world.setBlock(x + 2, y + 0, z + 5, ModBlocks.samStone, 1, 2);
		world.setBlock(x + 2, y + 0, z + 6, ModBlocks.samStone, 1, 2);
		world.setBlock(x + 2, y + 0, z + 7, ModBlocks.samStone, 1, 2);
		world.setBlock(x + 2, y + 0, z + 8, ModBlocks.samStone, 1, 2);
		world.setBlock(x + 2, y + 0, z + 9, ModBlocks.samStone, 1, 2);
		world.setBlock(x + 2, y + 0, z + 10, ModBlocks.samStone, 1, 2);
		world.setBlock(x + 2, y + 1, z + 0, ModBlocks.samStone, 1, 2);
		world.setBlock(x + 2, y + 1, z + 1, Blocks.air);
		world.setBlock(x + 2, y + 1, z + 2, Blocks.air);
		world.setBlock(x + 2, y + 1, z + 3, Blocks.air);
		world.setBlock(x + 2, y + 1, z + 4, Blocks.air);
		world.setBlock(x + 2, y + 1, z + 5, ModBlocks.samStone, 1, 2);
		world.setBlock(x + 2, y + 1, z + 6, Blocks.air);
		world.setBlock(x + 2, y + 1, z + 7, Blocks.air);
		world.setBlock(x + 2, y + 1, z + 8, Blocks.air);
		world.setBlock(x + 2, y + 1, z + 9, Blocks.air);
		world.setBlock(x + 2, y + 1, z + 10, ModBlocks.samStone, 1, 2);
		world.setBlock(x + 2, y + 2, z + 0, ModBlocks.samStone, 1, 2);
		world.setBlock(x + 2, y + 2, z + 1, Blocks.air);
		world.setBlock(x + 2, y + 2, z + 2, Blocks.air);
		world.setBlock(x + 2, y + 2, z + 3, Blocks.air);
		world.setBlock(x + 2, y + 2, z + 4, Blocks.air);
		world.setBlock(x + 2, y + 2, z + 5, Blocks.air);
		world.setBlock(x + 2, y + 2, z + 6, Blocks.air);
		world.setBlock(x + 2, y + 2, z + 7, Blocks.air);
		world.setBlock(x + 2, y + 2, z + 8, Blocks.air);
		world.setBlock(x + 2, y + 2, z + 9, Blocks.air);
		world.setBlock(x + 2, y + 2, z + 10, ModBlocks.samStone, 1, 2);
		world.setBlock(x + 2, y + 3, z + 0, ModBlocks.samStone, 1, 2);
		world.setBlock(x + 2, y + 3, z + 1, Blocks.air);
		world.setBlock(x + 2, y + 3, z + 2, Blocks.air);
		world.setBlock(x + 2, y + 3, z + 3, Blocks.air);
		world.setBlock(x + 2, y + 3, z + 4, Blocks.air);
		world.setBlock(x + 2, y + 3, z + 5, Blocks.air);
		world.setBlock(x + 2, y + 3, z + 6, Blocks.air);
		world.setBlock(x + 2, y + 3, z + 7, Blocks.air);
		world.setBlock(x + 2, y + 3, z + 8, Blocks.air);
		world.setBlock(x + 2, y + 3, z + 9, Blocks.air);
		world.setBlock(x + 2, y + 3, z + 10, ModBlocks.samStone, 1, 2);
		world.setBlock(x + 2, y + 4, z + 0, ModBlocks.samStone, 1, 2);
		world.setBlock(x + 2, y + 4, z + 1, Blocks.air);
		world.setBlock(x + 2, y + 4, z + 2, Blocks.air);
		world.setBlock(x + 2, y + 4, z + 3, Blocks.air);
		world.setBlock(x + 2, y + 4, z + 4, Blocks.air);
		world.setBlock(x + 2, y + 4, z + 5, Blocks.air);
		world.setBlock(x + 2, y + 4, z + 6, Blocks.air);
		world.setBlock(x + 2, y + 4, z + 7, Blocks.air);
		world.setBlock(x + 2, y + 4, z + 8, Blocks.air);
		world.setBlock(x + 2, y + 4, z + 9, Blocks.air);
		world.setBlock(x + 2, y + 4, z + 10, ModBlocks.samStone, 1, 2);
		world.setBlock(x + 2, y + 5, z + 0, ModBlocks.samStone, 1, 2);
		world.setBlock(x + 2, y + 5, z + 1, ModBlocks.samStone, 1, 2);
		world.setBlock(x + 2, y + 5, z + 2, ModBlocks.samStone, 1, 2);
		world.setBlock(x + 2, y + 5, z + 3, ModBlocks.samStone, 1, 2);
		world.setBlock(x + 2, y + 5, z + 4, ModBlocks.samStone, 1, 2);
		world.setBlock(x + 2, y + 5, z + 5, ModBlocks.samStone, 1, 2);
		world.setBlock(x + 2, y + 5, z + 6, ModBlocks.samStone, 1, 2);
		world.setBlock(x + 2, y + 5, z + 7, ModBlocks.samStone, 1, 2);
		world.setBlock(x + 2, y + 5, z + 8, ModBlocks.samStone, 1, 2);
		world.setBlock(x + 2, y + 5, z + 9, ModBlocks.samStone, 1, 2);
		world.setBlock(x + 2, y + 5, z + 10, ModBlocks.samStone, 1, 2);
		world.setBlock(x + 3, y + 0, z + 0, ModBlocks.samStone, 1, 2);
		world.setBlock(x + 3, y + 0, z + 1, ModBlocks.samStone, 1, 2);
		world.setBlock(x + 3, y + 0, z + 2, ModBlocks.samStone, 1, 2);
		world.setBlock(x + 3, y + 0, z + 3, ModBlocks.samStone, 1, 2);
		world.setBlock(x + 3, y + 0, z + 4, ModBlocks.samStone, 1, 2);
		world.setBlock(x + 3, y + 0, z + 5, ModBlocks.samStone, 1, 2);
		world.setBlock(x + 3, y + 0, z + 6, ModBlocks.samStone, 1, 2);
		world.setBlock(x + 3, y + 0, z + 7, ModBlocks.samStone, 1, 2);
		world.setBlock(x + 3, y + 0, z + 8, ModBlocks.samStone, 1, 2);
		world.setBlock(x + 3, y + 0, z + 9, ModBlocks.samStone, 1, 2);
		world.setBlock(x + 3, y + 0, z + 10, ModBlocks.samStone, 1, 2);
		world.setBlock(x + 3, y + 1, z + 0, ModBlocks.samStone, 1, 2);
		world.setBlock(x + 3, y + 1, z + 1, ModBlocks.samStone, 1, 2);
		world.setBlock(x + 3, y + 1, z + 2, ModBlocks.samStone, 1, 2);
		world.setBlock(x + 3, y + 1, z + 3, ModBlocks.samStone, 1, 2);
		world.setBlock(x + 3, y + 1, z + 4, Blocks.air);
		world.setBlock(x + 3, y + 1, z + 5, Blocks.air);
		world.setBlock(x + 3, y + 1, z + 6, Blocks.air);
		world.setBlock(x + 3, y + 1, z + 7, ModBlocks.samStone, 1, 2);
		world.setBlock(x + 3, y + 1, z + 8, ModBlocks.samStone, 1, 2);
		world.setBlock(x + 3, y + 1, z + 9, ModBlocks.samStone, 1, 2);
		world.setBlock(x + 3, y + 1, z + 10, ModBlocks.samStone, 1, 2);
		world.setBlock(x + 3, y + 2, z + 0, ModBlocks.samStone, 1, 2);
		world.setBlock(x + 3, y + 2, z + 1, ModBlocks.samStone, 1, 2);
		world.setBlock(x + 3, y + 2, z + 2, ModBlocks.samStone, 1, 2);
		world.setBlock(x + 3, y + 2, z + 3, Blocks.air);
		world.setBlock(x + 3, y + 2, z + 4, Blocks.air);
		world.setBlock(x + 3, y + 2, z + 5, Blocks.air);
		world.setBlock(x + 3, y + 2, z + 6, Blocks.air);
		world.setBlock(x + 3, y + 2, z + 7, Blocks.air);
		world.setBlock(x + 3, y + 2, z + 8, ModBlocks.samStone, 1, 2);
		world.setBlock(x + 3, y + 2, z + 9, ModBlocks.samStone, 1, 2);
		world.setBlock(x + 3, y + 2, z + 10, ModBlocks.samStone, 1, 2);
		world.setBlock(x + 3, y + 3, z + 0, ModBlocks.samStone, 1, 2);
		world.setBlock(x + 3, y + 3, z + 1, ModBlocks.samStone, 1, 2);
		world.setBlock(x + 3, y + 3, z + 2, Blocks.air);
		world.setBlock(x + 3, y + 3, z + 3, Blocks.air);
		world.setBlock(x + 3, y + 3, z + 4, Blocks.air);
		world.setBlock(x + 3, y + 3, z + 5, Blocks.air);
		world.setBlock(x + 3, y + 3, z + 6, Blocks.air);
		world.setBlock(x + 3, y + 3, z + 7, Blocks.air);
		world.setBlock(x + 3, y + 3, z + 8, Blocks.air);
		world.setBlock(x + 3, y + 3, z + 9, ModBlocks.samStone, 1, 2);
		world.setBlock(x + 3, y + 3, z + 10, ModBlocks.samStone, 1, 2);
		world.setBlock(x + 3, y + 4, z + 0, ModBlocks.samStone, 1, 2);
		world.setBlock(x + 3, y + 4, z + 1, Blocks.air);
		world.setBlock(x + 3, y + 4, z + 2, Blocks.air);
		world.setBlock(x + 3, y + 4, z + 3, Blocks.air);
		world.setBlock(x + 3, y + 4, z + 4, Blocks.air);
		world.setBlock(x + 3, y + 4, z + 5, Blocks.air);
		world.setBlock(x + 3, y + 4, z + 6, Blocks.air);
		world.setBlock(x + 3, y + 4, z + 7, Blocks.air);
		world.setBlock(x + 3, y + 4, z + 8, Blocks.air);
		world.setBlock(x + 3, y + 4, z + 9, Blocks.air);
		world.setBlock(x + 3, y + 4, z + 10, ModBlocks.samStone, 1, 2);
		world.setBlock(x + 3, y + 5, z + 0, ModBlocks.samStone, 1, 2);
		world.setBlock(x + 3, y + 5, z + 1, ModBlocks.samStone, 1, 2);
		world.setBlock(x + 3, y + 5, z + 2, ModBlocks.samStone, 1, 2);
		world.setBlock(x + 3, y + 5, z + 3, ModBlocks.samStone, 1, 2);
		world.setBlock(x + 3, y + 5, z + 4, ModBlocks.samStone, 1, 2);
		world.setBlock(x + 3, y + 5, z + 5, Blocks.glowstone);
		world.setBlock(x + 3, y + 5, z + 6, ModBlocks.samStone, 1, 2);
		world.setBlock(x + 3, y + 5, z + 7, ModBlocks.samStone, 1, 2);
		world.setBlock(x + 3, y + 5, z + 8, ModBlocks.samStone, 1, 2);
		world.setBlock(x + 3, y + 5, z + 9, ModBlocks.samStone, 1, 2);
		world.setBlock(x + 3, y + 5, z + 10, ModBlocks.samStone, 1, 2);
		world.setBlock(x + 4, y + 0, z + 0, ModBlocks.samStone, 1, 2);
		world.setBlock(x + 4, y + 0, z + 1, ModBlocks.samStone, 1, 2);
		world.setBlock(x + 4, y + 0, z + 2, ModBlocks.samStone, 1, 2);
		world.setBlock(x + 4, y + 0, z + 3, ModBlocks.samStone, 1, 2);
		world.setBlock(x + 4, y + 0, z + 4, ModBlocks.samStone, 1, 2);
		world.setBlock(x + 4, y + 0, z + 5, ModBlocks.samStone, 1, 2);
		world.setBlock(x + 4, y + 0, z + 6, ModBlocks.samStone, 1, 2);
		world.setBlock(x + 4, y + 0, z + 7, ModBlocks.samStone, 1, 2);
		world.setBlock(x + 4, y + 0, z + 8, ModBlocks.samStone, 1, 2);
		world.setBlock(x + 4, y + 0, z + 9, ModBlocks.samStone, 1, 2);
		world.setBlock(x + 4, y + 0, z + 10, ModBlocks.samStone, 1, 2);
		world.setBlock(x + 4, y + 1, z + 0, ModBlocks.samStone, 1, 2);
		world.setBlock(x + 4, y + 1, z + 1, Blocks.air);
		world.setBlock(x + 4, y + 1, z + 2, Blocks.air);
		world.setBlock(x + 4, y + 1, z + 3, Blocks.air);
		world.setBlock(x + 4, y + 1, z + 4, Blocks.air);
		world.setBlock(x + 4, y + 1, z + 5, Blocks.air);
		world.setBlock(x + 4, y + 1, z + 6, Blocks.air);
		world.setBlock(x + 4, y + 1, z + 7, Blocks.air);
		world.setBlock(x + 4, y + 1, z + 8, Blocks.air);
		world.setBlock(x + 4, y + 1, z + 9, Blocks.air);
		world.setBlock(x + 4, y + 1, z + 10, ModBlocks.samStone, 1, 2);
		world.setBlock(x + 4, y + 2, z + 0, ModBlocks.samStone, 1, 2);
		world.setBlock(x + 4, y + 2, z + 1, Blocks.air);
		world.setBlock(x + 4, y + 2, z + 2, Blocks.air);
		world.setBlock(x + 4, y + 2, z + 3, Blocks.air);
		world.setBlock(x + 4, y + 2, z + 4, Blocks.air);
		world.setBlock(x + 4, y + 2, z + 5, Blocks.air);
		world.setBlock(x + 4, y + 2, z + 6, Blocks.air);
		world.setBlock(x + 4, y + 2, z + 7, Blocks.air);
		world.setBlock(x + 4, y + 2, z + 8, Blocks.air);
		world.setBlock(x + 4, y + 2, z + 9, Blocks.air);
		world.setBlock(x + 4, y + 2, z + 10, ModBlocks.samStone, 1, 2);
		world.setBlock(x + 4, y + 3, z + 0, ModBlocks.samStone, 1, 2);
		world.setBlock(x + 4, y + 3, z + 1, Blocks.air);
		world.setBlock(x + 4, y + 3, z + 2, Blocks.air);
		world.setBlock(x + 4, y + 3, z + 3, Blocks.air);
		world.setBlock(x + 4, y + 3, z + 4, Blocks.air);
		world.setBlock(x + 4, y + 3, z + 5, Blocks.air);
		world.setBlock(x + 4, y + 3, z + 6, Blocks.air);
		world.setBlock(x + 4, y + 3, z + 7, Blocks.air);
		world.setBlock(x + 4, y + 3, z + 8, Blocks.air);
		world.setBlock(x + 4, y + 3, z + 9, Blocks.air);
		world.setBlock(x + 4, y + 3, z + 10, ModBlocks.samStone, 1, 2);
		world.setBlock(x + 4, y + 4, z + 0, ModBlocks.samStone, 1, 2);
		world.setBlock(x + 4, y + 4, z + 1, Blocks.air);
		world.setBlock(x + 4, y + 4, z + 2, Blocks.air);
		world.setBlock(x + 4, y + 4, z + 3, Blocks.air);
		world.setBlock(x + 4, y + 4, z + 4, Blocks.air);
		world.setBlock(x + 4, y + 4, z + 5, Blocks.air);
		world.setBlock(x + 4, y + 4, z + 6, Blocks.air);
		world.setBlock(x + 4, y + 4, z + 7, Blocks.air);
		world.setBlock(x + 4, y + 4, z + 8, Blocks.air);
		world.setBlock(x + 4, y + 4, z + 9, Blocks.air);
		world.setBlock(x + 4, y + 4, z + 10, ModBlocks.samStone, 1, 2);
		world.setBlock(x + 4, y + 5, z + 0, ModBlocks.samStone, 1, 2);
		world.setBlock(x + 4, y + 5, z + 1, ModBlocks.samStone, 1, 2);
		world.setBlock(x + 4, y + 5, z + 2, ModBlocks.samStone, 1, 2);
		world.setBlock(x + 4, y + 5, z + 3, ModBlocks.samStone, 1, 2);
		world.setBlock(x + 4, y + 5, z + 4, ModBlocks.samStone, 1, 2);
		world.setBlock(x + 4, y + 5, z + 5, ModBlocks.samStone, 1, 2);
		world.setBlock(x + 4, y + 5, z + 6, ModBlocks.samStone, 1, 2);
		world.setBlock(x + 4, y + 5, z + 7, ModBlocks.samStone, 1, 2);
		world.setBlock(x + 4, y + 5, z + 8, ModBlocks.samStone, 1, 2);
		world.setBlock(x + 4, y + 5, z + 9, ModBlocks.samStone, 1, 2);
		world.setBlock(x + 4, y + 5, z + 10, ModBlocks.samStone, 1, 2);
		world.setBlock(x + 5, y + 0, z + 0, ModBlocks.samStone, 1, 2);
		world.setBlock(x + 5, y + 0, z + 1, ModBlocks.samStone, 1, 2);
		world.setBlock(x + 5, y + 0, z + 2, ModBlocks.samStone, 1, 2);
		world.setBlock(x + 5, y + 0, z + 3, ModBlocks.samStone, 1, 2);
		world.setBlock(x + 5, y + 0, z + 4, ModBlocks.samStone, 1, 2);
		world.setBlock(x + 5, y + 0, z + 5, ModBlocks.samStone, 1, 2);
		world.setBlock(x + 5, y + 0, z + 6, ModBlocks.samStone, 1, 2);
		world.setBlock(x + 5, y + 0, z + 7, ModBlocks.samStone, 1, 2);
		world.setBlock(x + 5, y + 0, z + 8, ModBlocks.samStone, 1, 2);
		world.setBlock(x + 5, y + 0, z + 9, ModBlocks.samStone, 1, 2);
		world.setBlock(x + 5, y + 0, z + 10, ModBlocks.samStone, 1, 2);
		world.setBlock(x + 5, y + 1, z + 0, ModBlocks.samStone, 1, 2);
		world.setBlock(x + 5, y + 1, z + 1, Blocks.air);
		world.setBlock(x + 5, y + 1, z + 2, Blocks.air);
		world.setBlock(x + 5, y + 1, z + 3, Blocks.air);
		world.setBlock(x + 5, y + 1, z + 4, Blocks.air);
		world.setBlock(x + 5, y + 1, z + 5, ModBlocks.samStone, 1, 2);
		world.setBlock(x + 5, y + 1, z + 6, Blocks.air);
		world.setBlock(x + 5, y + 1, z + 7, Blocks.air);
		world.setBlock(x + 5, y + 1, z + 8, Blocks.air);
		world.setBlock(x + 5, y + 1, z + 9, Blocks.air);
		world.setBlock(x + 5, y + 1, z + 10, ModBlocks.samStone, 1, 2);
		world.setBlock(x + 5, y + 2, z + 0, ModBlocks.samStone, 1, 2);
		world.setBlock(x + 5, y + 2, z + 1, Blocks.air);
		world.setBlock(x + 5, y + 2, z + 2, Blocks.air);
		world.setBlock(x + 5, y + 2, z + 3, Blocks.air);
		world.setBlock(x + 5, y + 2, z + 4, Blocks.air);
		world.setBlock(x + 5, y + 2, z + 5, ModBlocks.samStone, 1, 2);
		world.setBlock(x + 5, y + 2, z + 6, Blocks.air);
		world.setBlock(x + 5, y + 2, z + 7, Blocks.air);
		world.setBlock(x + 5, y + 2, z + 8, Blocks.air);
		world.setBlock(x + 5, y + 2, z + 9, Blocks.air);
		world.setBlock(x + 5, y + 2, z + 10, ModBlocks.samStone, 1, 2);
		world.setBlock(x + 5, y + 3, z + 0, ModBlocks.samStone, 1, 2);
		world.setBlock(x + 5, y + 3, z + 1, Blocks.air);
		world.setBlock(x + 5, y + 3, z + 2, Blocks.air);
		world.setBlock(x + 5, y + 3, z + 3, Blocks.air);
		world.setBlock(x + 5, y + 3, z + 4, Blocks.air);
		world.setBlock(x + 5, y + 3, z + 5, Blocks.air);
		world.setBlock(x + 5, y + 3, z + 6, Blocks.air);
		world.setBlock(x + 5, y + 3, z + 7, Blocks.air);
		world.setBlock(x + 5, y + 3, z + 8, Blocks.air);
		world.setBlock(x + 5, y + 3, z + 9, Blocks.air);
		world.setBlock(x + 5, y + 3, z + 10, ModBlocks.samStone, 1, 2);
		world.setBlock(x + 5, y + 4, z + 0, ModBlocks.samStone, 1, 2);
		world.setBlock(x + 5, y + 4, z + 1, Blocks.air);
		world.setBlock(x + 5, y + 4, z + 2, Blocks.air);
		world.setBlock(x + 5, y + 4, z + 3, Blocks.air);
		world.setBlock(x + 5, y + 4, z + 4, Blocks.air);
		world.setBlock(x + 5, y + 4, z + 5, Blocks.air);
		world.setBlock(x + 5, y + 4, z + 6, Blocks.air);
		world.setBlock(x + 5, y + 4, z + 7, Blocks.air);
		world.setBlock(x + 5, y + 4, z + 8, Blocks.air);
		world.setBlock(x + 5, y + 4, z + 9, Blocks.air);
		world.setBlock(x + 5, y + 4, z + 10, ModBlocks.samStone, 1, 2);
		world.setBlock(x + 5, y + 5, z + 0, ModBlocks.samStone, 1, 2);
		world.setBlock(x + 5, y + 5, z + 1, ModBlocks.samStone, 1, 2);
		world.setBlock(x + 5, y + 5, z + 2, ModBlocks.samStone, 1, 2);
		world.setBlock(x + 5, y + 5, z + 3, ModBlocks.samStone, 1, 2);
		world.setBlock(x + 5, y + 5, z + 4, ModBlocks.samStone, 1, 2);
		world.setBlock(x + 5, y + 5, z + 5, ModBlocks.samStone, 1, 2);
		world.setBlock(x + 5, y + 5, z + 6, ModBlocks.samStone, 1, 2);
		world.setBlock(x + 5, y + 5, z + 7, ModBlocks.samStone, 1, 2);
		world.setBlock(x + 5, y + 5, z + 8, ModBlocks.samStone, 1, 2);
		world.setBlock(x + 5, y + 5, z + 9, ModBlocks.samStone, 1, 2);
		world.setBlock(x + 5, y + 5, z + 10, ModBlocks.samStone, 1, 2);
		world.setBlock(x + 6, y + 0, z + 0, ModBlocks.samStone, 1, 2);
		world.setBlock(x + 6, y + 0, z + 1, ModBlocks.samStone, 1, 2);
		world.setBlock(x + 6, y + 0, z + 2, ModBlocks.samStone, 1, 2);
		world.setBlock(x + 6, y + 0, z + 3, ModBlocks.samStone, 1, 2);
		world.setBlock(x + 6, y + 0, z + 4, ModBlocks.samStone, 1, 2);
		world.setBlock(x + 6, y + 0, z + 5, ModBlocks.samStone, 1, 2);
		world.setBlock(x + 6, y + 0, z + 6, ModBlocks.samStone, 1, 2);
		world.setBlock(x + 6, y + 0, z + 7, ModBlocks.samStone, 1, 2);
		world.setBlock(x + 6, y + 0, z + 8, ModBlocks.samStone, 1, 2);
		world.setBlock(x + 6, y + 0, z + 9, ModBlocks.samStone, 1, 2);
		world.setBlock(x + 6, y + 0, z + 10, ModBlocks.samStone, 1, 2);
		world.setBlock(x + 6, y + 1, z + 0, ModBlocks.samStone, 1, 2);
		world.setBlock(x + 6, y + 1, z + 1, ModBlocks.samStone, 1, 2);
		world.setBlock(x + 6, y + 1, z + 2, ModBlocks.samStone, 1, 2);
		world.setBlock(x + 6, y + 1, z + 3, ModBlocks.samStone, 1, 2);
		world.setBlock(x + 6, y + 1, z + 4, ModBlocks.samStone, 1, 2);
		world.setBlock(x + 6, y + 1, z + 5, ModBlocks.samStone, 1, 2);
		world.setBlock(x + 6, y + 1, z + 6, ModBlocks.samStone, 1, 2);
		world.setBlock(x + 6, y + 1, z + 7, ModBlocks.samStone, 1, 2);
		world.setBlock(x + 6, y + 1, z + 8, ModBlocks.samStone, 1, 2);
		world.setBlock(x + 6, y + 1, z + 9, ModBlocks.samStone, 1, 2);
		world.setBlock(x + 6, y + 1, z + 10, ModBlocks.samStone, 1, 2);
		world.setBlock(x + 6, y + 2, z + 0, ModBlocks.samStone, 1, 2);
		world.setBlock(x + 6, y + 2, z + 1, ModBlocks.samStone, 1, 2);
		world.setBlock(x + 6, y + 2, z + 2, ModBlocks.samStone, 1, 2);
		world.setBlock(x + 6, y + 2, z + 3, ModBlocks.samStone, 1, 2);
		world.setBlock(x + 6, y + 2, z + 4, ModBlocks.samStone, 1, 2);
		world.setBlock(x + 6, y + 2, z + 5, ModBlocks.samStone, 1, 2);
		world.setBlock(x + 6, y + 2, z + 6, ModBlocks.samStone, 1, 2);
		world.setBlock(x + 6, y + 2, z + 7, ModBlocks.samStone, 1, 2);
		world.setBlock(x + 6, y + 2, z + 8, ModBlocks.samStone, 1, 2);
		world.setBlock(x + 6, y + 2, z + 9, ModBlocks.samStone, 1, 2);
		world.setBlock(x + 6, y + 2, z + 10, ModBlocks.samStone, 1, 2);
		world.setBlock(x + 6, y + 3, z + 0, ModBlocks.samStone, 1, 2);
		world.setBlock(x + 6, y + 3, z + 1, ModBlocks.samStone, 1, 2);
		world.setBlock(x + 6, y + 3, z + 2, ModBlocks.samStone, 1, 2);
		world.setBlock(x + 6, y + 3, z + 3, ModBlocks.samStone, 1, 2);
		world.setBlock(x + 6, y + 3, z + 4, ModBlocks.samStone, 1, 2);
		world.setBlock(x + 6, y + 3, z + 5, ModBlocks.samStone, 1, 2);
		world.setBlock(x + 6, y + 3, z + 6, ModBlocks.samStone, 1, 2);
		world.setBlock(x + 6, y + 3, z + 7, ModBlocks.samStone, 1, 2);
		world.setBlock(x + 6, y + 3, z + 8, ModBlocks.samStone, 1, 2);
		world.setBlock(x + 6, y + 3, z + 9, ModBlocks.samStone, 1, 2);
		world.setBlock(x + 6, y + 3, z + 10, ModBlocks.samStone, 1, 2);
		world.setBlock(x + 6, y + 4, z + 0, ModBlocks.samStone, 1, 2);
		world.setBlock(x + 6, y + 4, z + 1, ModBlocks.samStone, 1, 2);
		world.setBlock(x + 6, y + 4, z + 2, ModBlocks.samStone, 1, 2);
		world.setBlock(x + 6, y + 4, z + 3, ModBlocks.samStone, 1, 2);
		world.setBlock(x + 6, y + 4, z + 4, ModBlocks.samStone, 1, 2);
		world.setBlock(x + 6, y + 4, z + 5, ModBlocks.samStone, 1, 2);
		world.setBlock(x + 6, y + 4, z + 6, ModBlocks.samStone, 1, 2);
		world.setBlock(x + 6, y + 4, z + 7, ModBlocks.samStone, 1, 2);
		world.setBlock(x + 6, y + 4, z + 8, ModBlocks.samStone, 1, 2);
		world.setBlock(x + 6, y + 4, z + 9, ModBlocks.samStone, 1, 2);
		world.setBlock(x + 6, y + 4, z + 10, ModBlocks.samStone, 1, 2);
		world.setBlock(x + 6, y + 5, z + 0, ModBlocks.samStone, 1, 2);
		world.setBlock(x + 6, y + 5, z + 1, ModBlocks.samStone, 1, 2);
		world.setBlock(x + 6, y + 5, z + 2, ModBlocks.samStone, 1, 2);
		world.setBlock(x + 6, y + 5, z + 3, ModBlocks.samStone, 1, 2);
		world.setBlock(x + 6, y + 5, z + 4, ModBlocks.samStone, 1, 2);
		world.setBlock(x + 6, y + 5, z + 5, ModBlocks.samStone, 1, 2);
		world.setBlock(x + 6, y + 5, z + 6, ModBlocks.samStone, 1, 2);
		world.setBlock(x + 6, y + 5, z + 7, ModBlocks.samStone, 1, 2);
		world.setBlock(x + 6, y + 5, z + 8, ModBlocks.samStone, 1, 2);
		world.setBlock(x + 6, y + 5, z + 9, ModBlocks.samStone, 1, 2);
		world.setBlock(x + 6, y + 5, z + 10, ModBlocks.samStone, 1, 2);

		return true;
	}
}